[2024-02-26T19:33:44.863+0000] {taskinstance.py:1956} INFO - Dependencies all met for dep_context=non-requeueable deps ti=<TaskInstance: cronTrigger.airflow manual__2024-02-26T19:33:30.509838+00:00 [queued]>
[2024-02-26T19:33:44.879+0000] {taskinstance.py:1956} INFO - Dependencies all met for dep_context=requeueable deps ti=<TaskInstance: cronTrigger.airflow manual__2024-02-26T19:33:30.509838+00:00 [queued]>
[2024-02-26T19:33:44.881+0000] {taskinstance.py:2170} INFO - Starting attempt 1 of 1
[2024-02-26T19:33:44.904+0000] {taskinstance.py:2191} INFO - Executing <Task(_PythonDecoratedOperator): airflow> on 2024-02-26 19:33:30.509838+00:00
[2024-02-26T19:33:44.912+0000] {standard_task_runner.py:60} INFO - Started process 917 to run task
[2024-02-26T19:33:44.917+0000] {standard_task_runner.py:87} INFO - Running: ['***', 'tasks', 'run', 'cronTrigger', '***', 'manual__2024-02-26T19:33:30.509838+00:00', '--job-id', '24', '--raw', '--subdir', 'DAGS_FOLDER/cronTrigger.py', '--cfg-path', '/tmp/tmpnugi77vq']
[2024-02-26T19:33:44.923+0000] {standard_task_runner.py:88} INFO - Job 24: Subtask ***
[2024-02-26T19:33:44.997+0000] {task_command.py:423} INFO - Running <TaskInstance: cronTrigger.airflow manual__2024-02-26T19:33:30.509838+00:00 [running]> on host 81dc7f67df81
[2024-02-26T19:33:45.133+0000] {taskinstance.py:2480} INFO - Exporting env vars: AIRFLOW_CTX_DAG_OWNER='***' AIRFLOW_CTX_DAG_ID='cronTrigger' AIRFLOW_CTX_TASK_ID='***' AIRFLOW_CTX_EXECUTION_DATE='2024-02-26T19:33:30.509838+00:00' AIRFLOW_CTX_TRY_NUMBER='1' AIRFLOW_CTX_DAG_RUN_ID='manual__2024-02-26T19:33:30.509838+00:00'
[2024-02-26T19:33:45.136+0000] {taskinstance.py:2698} ERROR - Task failed with exception
Traceback (most recent call last):
  File "/home/airflow/.local/lib/python3.8/site-packages/airflow/models/taskinstance.py", line 433, in _execute_task
    result = execute_callable(context=context, **execute_callable_kwargs)
  File "/home/airflow/.local/lib/python3.8/site-packages/airflow/decorators/base.py", line 241, in execute
    return_value = super().execute(context)
  File "/home/airflow/.local/lib/python3.8/site-packages/airflow/operators/python.py", line 199, in execute
    return_value = self.execute_callable()
  File "/home/airflow/.local/lib/python3.8/site-packages/airflow/operators/python.py", line 216, in execute_callable
    return self.python_callable(*self.op_args, **self.op_kwargs)
  File "/opt/airflow/dags/cronTrigger.py", line 14, in airflow
    val = selectOperator['ti'].xcom_pull(key='return_value',task_id="select_priority")
  File "/home/airflow/.local/lib/python3.8/site-packages/airflow/utils/session.py", line 79, in wrapper
    return func(*args, session=session, **kwargs)
TypeError: xcom_pull() got an unexpected keyword argument 'task_id'
[2024-02-26T19:33:45.166+0000] {taskinstance.py:1138} INFO - Marking task as FAILED. dag_id=cronTrigger, task_id=***, execution_date=20240226T193330, start_date=20240226T193344, end_date=20240226T193345
[2024-02-26T19:33:45.195+0000] {standard_task_runner.py:107} ERROR - Failed to execute job 24 for task *** (xcom_pull() got an unexpected keyword argument 'task_id'; 917)
[2024-02-26T19:33:45.211+0000] {local_task_job_runner.py:234} INFO - Task exited with return code 1
[2024-02-26T19:33:45.243+0000] {taskinstance.py:3280} INFO - 0 downstream tasks scheduled from follow-on schedule check
