[2024-02-26T17:20:10.264+0000] {taskinstance.py:1956} INFO - Dependencies all met for dep_context=non-requeueable deps ti=<TaskInstance: cronTrigger.airflow manual__2024-02-26T17:20:05.246110+00:00 [queued]>
[2024-02-26T17:20:10.273+0000] {taskinstance.py:1956} INFO - Dependencies all met for dep_context=requeueable deps ti=<TaskInstance: cronTrigger.airflow manual__2024-02-26T17:20:05.246110+00:00 [queued]>
[2024-02-26T17:20:10.274+0000] {taskinstance.py:2170} INFO - Starting attempt 1 of 1
[2024-02-26T17:20:10.291+0000] {taskinstance.py:2191} INFO - Executing <Task(_PythonDecoratedOperator): airflow> on 2024-02-26 17:20:05.246110+00:00
[2024-02-26T17:20:10.298+0000] {standard_task_runner.py:60} INFO - Started process 76 to run task
[2024-02-26T17:20:10.303+0000] {standard_task_runner.py:87} INFO - Running: ['***', 'tasks', 'run', 'cronTrigger', '***', 'manual__2024-02-26T17:20:05.246110+00:00', '--job-id', '5', '--raw', '--subdir', 'DAGS_FOLDER/cronTrigger.py', '--cfg-path', '/tmp/tmp2gpiy4h9']
[2024-02-26T17:20:10.307+0000] {standard_task_runner.py:88} INFO - Job 5: Subtask ***
[2024-02-26T17:20:10.384+0000] {task_command.py:423} INFO - Running <TaskInstance: cronTrigger.airflow manual__2024-02-26T17:20:05.246110+00:00 [running]> on host ea3eaf80986c
[2024-02-26T17:20:10.556+0000] {taskinstance.py:2480} INFO - Exporting env vars: AIRFLOW_CTX_DAG_OWNER='***' AIRFLOW_CTX_DAG_ID='cronTrigger' AIRFLOW_CTX_TASK_ID='***' AIRFLOW_CTX_EXECUTION_DATE='2024-02-26T17:20:05.246110+00:00' AIRFLOW_CTX_TRY_NUMBER='1' AIRFLOW_CTX_DAG_RUN_ID='manual__2024-02-26T17:20:05.246110+00:00'
[2024-02-26T17:20:10.576+0000] {taskinstance.py:2698} ERROR - Task failed with exception
Traceback (most recent call last):
  File "/home/airflow/.local/lib/python3.8/site-packages/airflow/models/taskinstance.py", line 433, in _execute_task
    result = execute_callable(context=context, **execute_callable_kwargs)
  File "/home/airflow/.local/lib/python3.8/site-packages/airflow/decorators/base.py", line 241, in execute
    return_value = super().execute(context)
  File "/home/airflow/.local/lib/python3.8/site-packages/airflow/operators/python.py", line 199, in execute
    return_value = self.execute_callable()
  File "/home/airflow/.local/lib/python3.8/site-packages/airflow/operators/python.py", line 216, in execute_callable
    return self.python_callable(*self.op_args, **self.op_kwargs)
  File "/opt/airflow/dags/cronTrigger.py", line 13, in airflow
    logging.info("custom log ",Variable.get('DB_PASSWORD'))
  File "/home/airflow/.local/lib/python3.8/site-packages/airflow/models/variable.py", line 143, in get
    raise KeyError(f"Variable {key} does not exist")
KeyError: 'Variable DB_PASSWORD does not exist'
[2024-02-26T17:20:10.601+0000] {taskinstance.py:1138} INFO - Marking task as FAILED. dag_id=cronTrigger, task_id=***, execution_date=20240226T172005, start_date=20240226T172010, end_date=20240226T172010
[2024-02-26T17:20:10.637+0000] {standard_task_runner.py:107} ERROR - Failed to execute job 5 for task *** ('Variable DB_PASSWORD does not exist'; 76)
[2024-02-26T17:20:10.679+0000] {local_task_job_runner.py:234} INFO - Task exited with return code 1
[2024-02-26T17:20:10.706+0000] {taskinstance.py:3280} INFO - 0 downstream tasks scheduled from follow-on schedule check
