[2024-02-26T18:33:10.583+0000] {taskinstance.py:1956} INFO - Dependencies all met for dep_context=non-requeueable deps ti=<TaskInstance: cronTrigger.select_priority manual__2024-02-26T18:33:06.338732+00:00 [queued]>
[2024-02-26T18:33:10.607+0000] {taskinstance.py:1956} INFO - Dependencies all met for dep_context=requeueable deps ti=<TaskInstance: cronTrigger.select_priority manual__2024-02-26T18:33:06.338732+00:00 [queued]>
[2024-02-26T18:33:10.608+0000] {taskinstance.py:2170} INFO - Starting attempt 1 of 1
[2024-02-26T18:33:10.645+0000] {taskinstance.py:2191} INFO - Executing <Task(PostgresOperator): select_priority> on 2024-02-26 18:33:06.338732+00:00
[2024-02-26T18:33:10.654+0000] {standard_task_runner.py:60} INFO - Started process 146 to run task
[2024-02-26T18:33:10.661+0000] {standard_task_runner.py:87} INFO - Running: ['***', 'tasks', 'run', 'cronTrigger', 'select_priority', 'manual__2024-02-26T18:33:06.338732+00:00', '--job-id', '14', '--raw', '--subdir', 'DAGS_FOLDER/cronTrigger.py', '--cfg-path', '/tmp/tmpe1uv92u1']
[2024-02-26T18:33:10.665+0000] {standard_task_runner.py:88} INFO - Job 14: Subtask select_priority
[2024-02-26T18:33:10.742+0000] {task_command.py:423} INFO - Running <TaskInstance: cronTrigger.select_priority manual__2024-02-26T18:33:06.338732+00:00 [running]> on host 81dc7f67df81
[2024-02-26T18:33:10.926+0000] {taskinstance.py:2480} INFO - Exporting env vars: AIRFLOW_CTX_DAG_OWNER='***' AIRFLOW_CTX_DAG_ID='cronTrigger' AIRFLOW_CTX_TASK_ID='select_priority' AIRFLOW_CTX_EXECUTION_DATE='2024-02-26T18:33:06.338732+00:00' AIRFLOW_CTX_TRY_NUMBER='1' AIRFLOW_CTX_DAG_RUN_ID='manual__2024-02-26T18:33:06.338732+00:00'
[2024-02-26T18:33:10.940+0000] {sql.py:276} INFO - Executing: select * from priorities
[2024-02-26T18:33:10.957+0000] {base.py:83} INFO - Using connection ID 'postgres_local' for task execution.
[2024-02-26T18:33:10.984+0000] {base.py:83} INFO - Using connection ID 'postgres_local' for task execution.
[2024-02-26T18:33:10.987+0000] {taskinstance.py:2698} ERROR - Task failed with exception
Traceback (most recent call last):
  File "/home/airflow/.local/lib/python3.8/site-packages/airflow/models/taskinstance.py", line 433, in _execute_task
    result = execute_callable(context=context, **execute_callable_kwargs)
  File "/home/airflow/.local/lib/python3.8/site-packages/airflow/providers/common/sql/operators/sql.py", line 282, in execute
    output = hook.run(
  File "/home/airflow/.local/lib/python3.8/site-packages/airflow/providers/common/sql/hooks/sql.py", line 391, in run
    with closing(self.get_conn()) as conn:
  File "/home/airflow/.local/lib/python3.8/site-packages/airflow/providers/postgres/hooks/postgres.py", line 158, in get_conn
    self.conn = psycopg2.connect(**conn_args)
  File "/home/airflow/.local/lib/python3.8/site-packages/psycopg2/__init__.py", line 122, in connect
    conn = _connect(dsn, connection_factory=connection_factory, **kwasync)
psycopg2.OperationalError: connection to server at "12b50ecaa6ea" (172.23.0.3), port 5433 failed: Connection refused
	Is the server running on that host and accepting TCP/IP connections?

[2024-02-26T18:33:11.008+0000] {taskinstance.py:1138} INFO - Marking task as FAILED. dag_id=cronTrigger, task_id=select_priority, execution_date=20240226T183306, start_date=20240226T183310, end_date=20240226T183311
[2024-02-26T18:33:11.042+0000] {standard_task_runner.py:107} ERROR - Failed to execute job 14 for task select_priority (connection to server at "12b50ecaa6ea" (172.23.0.3), port 5433 failed: Connection refused
	Is the server running on that host and accepting TCP/IP connections?
; 146)
[2024-02-26T18:33:11.075+0000] {local_task_job_runner.py:234} INFO - Task exited with return code 1
[2024-02-26T18:33:11.117+0000] {taskinstance.py:3280} INFO - 0 downstream tasks scheduled from follow-on schedule check
